I'm sorry, but an uncaught exception occurred.

While running game code:
  File "game/script_timur_ch3.rpy", line 222, in script
    scene bg_room_repair_night with diss
  File "game/script_timur_ch3.rpy", line 222, in <module>
    scene bg_room_repair_night with diss
NameError: name 'diss' is not defined

-- Full Traceback ------------------------------------------------------------

Full traceback:
  File "game/script_timur_ch3.rpy", line 222, in script
    scene bg_room_repair_night with diss
  File "B:\renpy-8.3.4-sdk\renpy\ast.py", line 1363, in execute
    paired = renpy.python.py_eval(self.paired)
  File "B:\renpy-8.3.4-sdk\renpy\python.py", line 1209, in py_eval
    return py_eval_bytecode(code, globals, locals)
  File "B:\renpy-8.3.4-sdk\renpy\python.py", line 1202, in py_eval_bytecode
    return eval(bytecode, globals, locals)
  File "game/script_timur_ch3.rpy", line 222, in <module>
    scene bg_room_repair_night with diss
NameError: name 'diss' is not defined

Windows-10-10.0.22631 AMD64
Ren'Py 8.3.4.24120703
Ты не один 0.1
Sun Feb  9 16:56:27 2025
